Workbook

Sheet Dashboard
B2: AI IMPLOSION DASHBOARD
B3: Built by KK Reddy
B4: ="7 AI-cycle drawdowns + HY spread | Data as of "&TEXT(MAX(tblHistory[Date]),"dd-mmm-yyyy")
B7: STRESS SCORE | D7: STATUS | F7: TRIGGERS | H7: CURRENT LEVEL | J7: BET COUNTDOWN
B8: =Tracker!C5 | D8: =Tracker!C7 | F8: =Tracker!C6 | H8: =Tracker!C17 | J8: ="KK "&Tracker!D22&"d | SJ "&Tracker!D23&"d"
B9: ="out of 100" | D9: ="Score band" | F9: ="factors at stress 100%" | H9: ="5 straight days rule" | J9: ="Winner: "&Tracker!C25
B11: FACTOR DETAIL
B12: Metric | C12: Weight | D12: 52W High (HY: 52W Low) | E12: Current | F12: Drawdown (HY: +bp vs low) | G12: Calm | H12: Trigger | I12: Trigger price (HY: band) | J12: Stress | K12: Status
B13: Nasdaq-100 (NDX) | C13: 0.18 | D13: =_xlfn.MAXIFS(tblHistory[NDX],tblHistory[Date],"<="&MAX(tblHistory[Date]),tblHistory[Date],">="&MAX(tblHistory[Date])-365) | E13: =SUMIFS(tblHistory[NDX],tblHistory[Date],_xlfn.MAXIFS(tblHistory[Date],tblHistory[NDX],"<>")) | F13: =E13/D13-1 | G13: -0.05 | H13: -0.25 | I13: =D13*(1+H13) | J13: =MIN(1,MAX(0,(F13-G13)/(H13-G13))) | K13: =IF(J13=1,"TRIGGERED",IF(J13>=0.5,"WARNING",IF(J13>0,"WATCH","CALM")))
B14: Semis (SOX) | C14: 0.18 | D14: =_xlfn.MAXIFS(tblHistory[SOX],tblHistory[Date],"<="&MAX(tblHistory[Date]),tblHistory[Date],">="&MAX(tblHistory[Date])-365) | E14: =SUMIFS(tblHistory[SOX],tblHistory[Date],_xlfn.MAXIFS(tblHistory[Date],tblHistory[SOX],"<>")) | F14: =E14/D14-1 | G14: -0.1 | H14: -0.4 | I14: =D14*(1+H14) | J14: =MIN(1,MAX(0,(F14-G14)/(H14-G14))) | K14: =IF(J14=1,"TRIGGERED",IF(J14>=0.5,"WARNING",IF(J14>0,"WATCH","CALM")))
B15: AI ETF (AIQ) | C15: 0.09 | D15: =_xlfn.MAXIFS(tblHistory[AIQ],tblHistory[Date],"<="&MAX(tblHistory[Date]),tblHistory[Date],">="&MAX(tblHistory[Date])-365) | E15: =SUMIFS(tblHistory[AIQ],tblHistory[Date],_xlfn.MAXIFS(tblHistory[Date],tblHistory[AIQ],"<>")) | F15: =E15/D15-1 | G15: -0.05 | H15: -0.3 | I15: =D15*(1+H15) | J15: =MIN(1,MAX(0,(F15-G15)/(H15-G15))) | K15: =IF(J15=1,"TRIGGERED",IF(J15>=0.5,"WARNING",IF(J15>0,"WATCH","CALM")))
B16: Oracle (ORCL) | C16: 0.09 | D16: =_xlfn.MAXIFS(tblHistory[ORCL],tblHistory[Date],"<="&MAX(tblHistory[Date]),tblHistory[Date],">="&MAX(tblHistory[Date])-365) | E16: =SUMIFS(tblHistory[ORCL],tblHistory[Date],_xlfn.MAXIFS(tblHistory[Date],tblHistory[ORCL],"<>")) | F16: =E16/D16-1 | G16: -0.15 | H16: -0.5 | I16: =D16*(1+H16) | J16: =MIN(1,MAX(0,(F16-G16)/(H16-G16))) | K16: =IF(J16=1,"TRIGGERED",IF(J16>=0.5,"WARNING",IF(J16>0,"WATCH","CALM")))
B17: CoreWeave (CRWV) | C17: 0.09 | D17: =_xlfn.MAXIFS(tblHistory[CRWV],tblHistory[Date],"<="&MAX(tblHistory[Date]),tblHistory[Date],">="&MAX(tblHistory[Date])-365) | E17: =SUMIFS(tblHistory[CRWV],tblHistory[Date],_xlfn.MAXIFS(tblHistory[Date],tblHistory[CRWV],"<>")) | F17: =E17/D17-1 | G17: -0.3 | H17: -0.6 | I17: =D17*(1+H17) | J17: =MIN(1,MAX(0,(F17-G17)/(H17-G17))) | K17: =IF(J17=1,"TRIGGERED",IF(J17>=0.5,"WARNING",IF(J17>0,"WATCH","CALM")))
B18: BDC ETF (BIZD) | C18: 0.14 | D18: =_xlfn.MAXIFS(tblHistory[BIZD],tblHistory[Date],"<="&MAX(tblHistory[Date]),tblHistory[Date],">="&MAX(tblHistory[Date])-365) | E18: =SUMIFS(tblHistory[BIZD],tblHistory[Date],_xlfn.MAXIFS(tblHistory[Date],tblHistory[BIZD],"<>")) | F18: =E18/D18-1 | G18: -0.05 | H18: -0.25 | I18: =D18*(1+H18) | J18: =MIN(1,MAX(0,(F18-G18)/(H18-G18))) | K18: =IF(J18=1,"TRIGGERED",IF(J18>=0.5,"WARNING",IF(J18>0,"WATCH","CALM")))
B19: Loan ETF (BKLN) | C19: 0.13 | D19: =_xlfn.MAXIFS(tblHistory[BKLN],tblHistory[Date],"<="&MAX(tblHistory[Date]),tblHistory[Date],">="&MAX(tblHistory[Date])-365) | E19: =SUMIFS(tblHistory[BKLN],tblHistory[Date],_xlfn.MAXIFS(tblHistory[Date],tblHistory[BKLN],"<>")) | F19: =E19/D19-1 | G19: -0.02 | H19: -0.08 | I19: =D19*(1+H19) | J19: =MIN(1,MAX(0,(F19-G19)/(H19-G19))) | K19: =IF(J19=1,"TRIGGERED",IF(J19>=0.5,"WARNING",IF(J19>0,"WATCH","CALM")))
B20: HY OAS (bp) (HY) | C20: 0.1 | D20: =_xlfn.MINIFS(tblHistory[HY],tblHistory[Date],"<="&MAX(tblHistory[Date]),tblHistory[Date],">="&MAX(tblHistory[Date])-365) | E20: =SUMIFS(tblHistory[HY],tblHistory[Date],_xlfn.MAXIFS(tblHistory[Date],tblHistory[HY],"<>")) | F20: =E20-D20 | G20: 400 | H20: 600 | I20: =IF(E20<300,"Very Healthy",IF(E20<400,"Normal",IF(E20<500,"Watch",IF(E20<600,"Warning",IF(E20<800,"Severe Stress","Crisis"))))) | J20: =MIN(1,MAX(0,(E20-G20)/(H20-G20))) | K20: =IF(J20=1,"TRIGGERED",IF(J20>=0.5,"WARNING",IF(J20>0,"WATCH","CALM")))
B21: Total weight | C21: =SUM(C13:C20)
B22: How it works: Drawdown = close ÷ trailing-365-day high − 1 (HY uses spread level in bp). Stress = clamp((x − Calm)/(Trigger − Calm), 0, 1). Score = weighted stress × 100. Levels need 5 straight trading days: L1 Score≥50 · L2 Score≥60 + BIZD≥80% + BKLN≥50% · L3 Score≥70 + SOX≥83% + AIQ≥80% · L4 Score≥75 + NDX=100% + (HY≥500bp or BIZD=100%). Implosion date = first day of the first L4 streak. Blue cells are editable.
B77: AI Implosion Dashboard · designed by KK Reddy

Sheet Tracker
B2: TRACKER — score, levels & bet
B4: Latest date | C4: =MAX(tblHistory[Date])
B5: Score | C5: =INDEX(tblHistory[Score],MATCH(C4,tblHistory[Date],0))
B6: Triggers | C6: =COUNTIF(Dashboard!K13:K20,"TRIGGERED")&" of 8"
B7: Band | C7: =IF(C18<>"","IMPLOSION CONFIRMED",IFERROR(IF(C5<25,"NORMAL",IF(C5<50,"ELEVATED",IF(C5<75,"SEVERE","CRITICAL"))),"WARM-UP"))
B10: LEVELS
B11: Level | C11: Name | D11: First date (5-day start) | E11: Active now
B12: L1 | C12: Warning | D12: =IF(COUNTIF(tblHistory[L1S],1),_xlfn.MINIFS(tblHistory[Date],tblHistory[L1S],1),"") | E12: =IF(COUNTIFS(tblHistory[Date],">="&LARGE(tblHistory[Date],5),tblHistory[L1],1)=5,"YES","NO")
B13: L2 | C13: Financing Stress | D13: =IF(COUNTIF(tblHistory[L2S],1),_xlfn.MINIFS(tblHistory[Date],tblHistory[L2S],1),"") | E13: =IF(COUNTIFS(tblHistory[Date],">="&LARGE(tblHistory[Date],5),tblHistory[L2],1)=5,"YES","NO")
B14: L3 | C14: Bubble Unwind | D14: =IF(COUNTIF(tblHistory[L3S],1),_xlfn.MINIFS(tblHistory[Date],tblHistory[L3S],1),"") | E14: =IF(COUNTIFS(tblHistory[Date],">="&LARGE(tblHistory[Date],5),tblHistory[L3],1)=5,"YES","NO")
B15: L4 | C15: AI Implosion | D15: =IF(COUNTIF(tblHistory[L4S],1),_xlfn.MINIFS(tblHistory[Date],tblHistory[L4S],1),"") | E15: =IF(COUNTIFS(tblHistory[Date],">="&LARGE(tblHistory[Date],5),tblHistory[L4],1)=5,"YES","NO")
B17: Current level | C17: =IF(E15="YES","L4 AI Implosion",IF(E14="YES","L3 Bubble Unwind",IF(E13="YES","L2 Financing Stress",IF(E12="YES","L1 Warning","None"))))
B18: AI Implosion date | C18: =D15
B20: THE BET
B21: Player | C21: Pick | D21: Days left | E21: Days off
B22: KK | C22: 46418 | D22: =MAX(0,C22-TODAY()) | E22: =IF($C$18="","",ABS($C$18-C22))
B23: SJ | C23: 46568 | D23: =MAX(0,C23-TODAY()) | E23: =IF($C$18="","",ABS($C$18-C23))
B25: Winner | C25: =IF(C18="","TBD",IF(E22<E23,"KK",IF(E23<E22,"SJ","TIE")))

Sheet History
A1: SAMPLE DATA — illustrative random-walk prices, NOT real market history. Run update_dashboard.py to load real data.
A2: Inputs: Date + 8 closes (light blue). Everything from 'NDX S' onward is calculated — don't type there. Blank HY = carry last value.
A3: Date | B3: NDX | C3: SOX | D3: AIQ | E3: ORCL | F3: CRWV | G3: BIZD | H3: BKLN | I3: HY | J3: NDX S | K3: SOX S | L3: AIQ S | M3: ORCL S | N3: CRWV S | O3: BIZD S | P3: BKLN S | Q3: HY S | R3: EquityP | S3: FinP | T3: CreditP | U3: Score | V3: L1 | W3: L2 | X3: L3 | Y3: L4 | Z3: L1S | AA3: L2S | AB3: L3S | AC3: L4S
A4: 46310 | B4: 24099.46 | C4: 9364.68 | D4: 39.07 | E4: 188.77 | F4: 33.59 | G4: 15.68 | H4: 20.84 | I4: 405 | J4: =IF(tblHistory[[#This Row],[Date]]-MIN(tblHistory[Date])<364,NA(),IF(ISNUMBER(tblHistory[[#This Row],[NDX]]),MIN(1,MAX(0,((tblHistory[[#This Row],[NDX]]/_xlfn.MAXIFS(tblHistory[NDX],tblHistory[Date],"<="&tblHistory[[#This Row],[Date]],tblHistory[Date],">="&tblHistory[[#This Row],[Date]]-365)-1)-Dashboard!$G$13)/(Dashboard!$H$13-Dashboard!$G$13))),0)) | K4: =IF(tblHistory[[#This Row],[Date]]-MIN(tblHistory[Date])<364,NA(),IF(ISNUMBER(tblHistory[[#This Row],[SOX]]),MIN(1,MAX(0,((tblHistory[[#This Row],[SOX]]/_xlfn.MAXIFS(tblHistory[SOX],tblHistory[Date],"<="&tblHistory[[#This Row],[Date]],tblHistory[Date],">="&tblHistory[[#This Row],[Date]]-365)-1)-Dashboard!$G$14)/(Dashboard!$H$14-Dashboard!$G$14))),0)) | L4: =IF(tblHistory[[#This Row],[Date]]-MIN(tblHistory[Date])<364,NA(),IF(ISNUMBER(tblHistory[[#This Row],[AIQ]]),MIN(1,MAX(0,((tblHistory[[#This Row],[AIQ]]/_xlfn.MAXIFS(tblHistory[AIQ],tblHistory[Date],"<="&tblHistory[[#This Row],[Date]],tblHistory[Date],">="&tblHistory[[#This Row],[Date]]-365)-1)-Dashboard!$G$15)/(Dashboard!$H$15-Dashboard!$G$15))),0)) | M4: =IF(tblHistory[[#This Row],[Date]]-MIN(tblHistory[Date])<364,NA(),IF(ISNUMBER(tblHistory[[#This Row],[ORCL]]),MIN(1,MAX(0,((tblHistory[[#This Row],[ORCL]]/_xlfn.MAXIFS(tblHistory[ORCL],tblHistory[Date],"<="&tblHistory[[#This Row],[Date]],tblHistory[Date],">="&tblHistory[[#This Row],[Date]]-365)-1)-Dashboard!$G$16)/(Dashboard!$H$16-Dashboard!$G$16))),0)) | N4: =IF(tblHistory[[#This Row],[Date]]-MIN(tblHistory[Date])<364,NA(),IF(ISNUMBER(tblHistory[[#This Row],[CRWV]]),MIN(1,MAX(0,((tblHistory[[#This Row],[CRWV]]/_xlfn.MAXIFS(tblHistory[CRWV],tblHistory[Date],"<="&tblHistory[[#This Row],[Date]],tblHistory[Date],">="&tblHistory[[#This Row],[Date]]-365)-1)-Dashboard!$G$17)/(Dashboard!$H$17-Dashboard!$G$17))),0)) | O4: =IF(tblHistory[[#This Row],[Date]]-MIN(tblHistory[Date])<364,NA(),IF(ISNUMBER(tblHistory[[#This Row],[BIZD]]),MIN(1,MAX(0,((tblHistory[[#This Row],[BIZD]]/_xlfn.MAXIFS(tblHistory[BIZD],tblHistory[Date],"<="&tblHistory[[#This Row],[Date]],tblHistory[Date],">="&tblHistory[[#This Row],[Date]]-365)-1)-Dashboard!$G$18)/(Dashboard!$H$18-Dashboard!$G$18))),0)) | P4: =IF(tblHistory[[#This Row],[Date]]-MIN(tblHistory[Date])<364,NA(),IF(ISNUMBER(tblHistory[[#This Row],[BKLN]]),MIN(1,MAX(0,((tblHistory[[#This Row],[BKLN]]/_xlfn.MAXIFS(tblHistory[BKLN],tblHistory[Date],"<="&tblHistory[[#This Row],[Date]],tblHistory[Date],">="&tblHistory[[#This Row],[Date]]-365)-1)-Dashboard!$G$19)/(Dashboard!$H$19-Dashboard!$G$19))),0)) | Q4: =IF(tblHistory[[#This Row],[Date]]-MIN(tblHistory[Date])<364,NA(),MIN(1,MAX(0,(IF(ISNUMBER(tblHistory[[#This Row],[HY]]),tblHistory[[#This Row],[HY]],SUMIFS(tblHistory[HY],tblHistory[Date],_xlfn.MAXIFS(tblHistory[Date],tblHistory[Date],"<"&tblHistory[[#This Row],[Date]],tblHistory[HY],"<>")))-Dashboard!$G$20)/(Dashboard!$H$20-Dashboard!$G$20)))) | R4: =(Dashboard!$C$13*tblHistory[[#This Row],[NDX S]]+Dashboard!$C$14*tblHistory[[#This Row],[SOX S]]+Dashboard!$C$15*tblHistory[[#This Row],[AIQ S]])/SUM(Dashboard!$C$13:$C$15)*100 | S4: =(Dashboard!$C$16*tblHistory[[#This Row],[ORCL S]]+Dashboard!$C$17*tblHistory[[#This Row],[CRWV S]])/SUM(Dashboard!$C$16:$C$17)*100 | T4: =(Dashboard!$C$18*tblHistory[[#This Row],[BIZD S]]+Dashboard!$C$19*tblHistory[[#This Row],[BKLN S]]+Dashboard!$C$20*tblHistory[[#This Row],[HY S]])/SUM(Dashboard!$C$18:$C$20)*100 | U4: =ROUND((Dashboard!$C$13*tblHistory[[#This Row],[NDX S]]+Dashboard!$C$14*tblHistory[[#This Row],[SOX S]]+Dashboard!$C$15*tblHistory[[#This Row],[AIQ S]]+Dashboard!$C$16*tblHistory[[#This Row],[ORCL S]]+Dashboard!$C$17*tblHistory[[#This Row],[CRWV S]]+Dashboard!$C$18*tblHistory[[#This Row],[BIZD S]]+Dashboard!$C$19*tblHistory[[#This Row],[BKLN S]]+Dashboard!$C$20*tblHistory[[#This Row],[HY S]])/SUM(Dashboard!$C$13:$C$20)*100,0) | V4: =IFERROR(--(tblHistory[[#This Row],[Score]]>=50),0) | W4: =IFERROR(--AND(tblHistory[[#This Row],[Score]]>=60,tblHistory[[#This Row],[BIZD S]]>=0.8,tblHistory[[#This Row],[BKLN S]]>=0.5),0) | X4: =IFERROR(--AND(tblHistory[[#This Row],[Score]]>=70,tblHistory[[#This Row],[SOX S]]>=0.83,tblHistory[[#This Row],[AIQ S]]>=0.8),0) | Y4: =IFERROR(--AND(tblHistory[[#This Row],[Score]]>=75,tblHistory[[#This Row],[NDX S]]=1,OR(IF(ISNUMBER(tblHistory[[#This Row],[HY]]),tblHistory[[#This Row],[HY]],SUMIFS(tblHistory[HY],tblHistory[Date],_xlfn.MAXIFS(tblHistory[Date],tblHistory[Date],"<"&tblHistory[[#This Row],[Date]],tblHistory[HY],"<>")))>=500,tblHistory[[#This Row],[BIZD S]]=1)),0) | Z4: =IFERROR(--(COUNTIFS(tblHistory[Date],">="&tblHistory[[#This Row],[Date]],tblHistory[Date],"<="&_xlfn.AGGREGATE(15,6,tblHistory[Date]/(tblHistory[Date]>=tblHistory[[#This Row],[Date]]),5),tblHistory[L1],1)=5),0) | AA4: =IFERROR(--(COUNTIFS(tblHistory[Date],">="&tblHistory[[#This Row],[Date]],tblHistory[Date],"<="&_xlfn.AGGREGATE(15,6,tblHistory[Date]/(tblHistory[Date]>=tblHistory[[#This Row],[Date]]),5),tblHistory[L2],1)=5),0) | AB4: =IFERROR(--(COUNTIFS(tblHistory[Date],">="&tblHistory[[#This Row],[Date]],tblHistory[Date],"<="&_xlfn.AGGREGATE(15,6,tblHistory[Date]/(tblHistory[Date]>=tblHistory[[#This Row],[Date]]),5),tblHistory[L3],1)=5),0) | AC4: =IFERROR(--(COUNTIFS(tblHistory[Date],">="&tblHistory[[#This Row],[Date]],tblHistory[Date],"<="&_xlfn.AGGREGATE(15,6,tblHistory[Date]/(tblHistory[Date]>=tblHistory[[#This Row],[Date]]),5),tblHistory[L4],1)=5),0)
A5: 46309 | B5: 24395.61 | C5: 9084.88 | D5: 39.06 | E5: 192.34 | F5: 33.14 | G5: 15.92 | H5: 20.78 | I5: 408 | J5: =IF(tblHistory[[#This Row],[Date]]-MIN(tblHistory[Date])<364,NA(),IF(ISNUMBER(tblHistory[[#This Row],[NDX]]),MIN(1,MAX(0,((tblHistory[[#This Row],[NDX]]/_xlfn.MAXIFS(tblHistory[NDX],tblHistory[Date],"<="&tblHistory[[#This Row],[Date]],tblHistory[Date],">="&tblHistory[[#This Row],[Date]]-365)-1)-Dashboard!$G$13)/(Dashboard!$H$13-Dashboard!$G$13))),0)) | K5: =IF(tblHistory[[#This Row],[Date]]-MIN(tblHistory[Date])<364,NA(),IF(ISNUMBER(tblHistory[[#This Row],[SOX]]),MIN(1,MAX(0,((tblHistory[[#This Row],[SOX]]/_xlfn.MAXIFS(tblHistory[SOX],tblHistory[Date],"<="&tblHistory[[#This Row],[Date]],tblHistory[Date],">="&tblHistory[[#This Row],[Date]]-365)-1)-Dashboard!$G$14)/(Dashboard!$H$14-Dashboard!$G$14))),0)) | L5: =IF(tblHistory[[#This Row],[Date]]-MIN(tblHistory[Date])<364,NA(),IF(ISNUMBER(tblHistory[[#This Row],[AIQ]]),MIN(1,MAX(0,((tblHistory[[#This Row],[AIQ]]/_xlfn.MAXIFS(tblHistory[AIQ],tblHistory[Date],"<="&tblHistory[[#This Row],[Date]],tblHistory[Date],">="&tblHistory[[#This Row],[Date]]-365)-1)-Dashboard!$G$15)/(Dashboard!$H$15-Dashboard!$G$15))),0)) | M5: =IF(tblHistory[[#This Row],[Date]]-MIN(tblHistory[Date])<364,NA(),IF(ISNUMBER(tblHistory[[#This Row],[ORCL]]),MIN(1,MAX(0,((tblHistory[[#This Row],[ORCL]]/_xlfn.MAXIFS(tblHistory[ORCL],tblHistory[Date],"<="&tblHistory[[#This Row],[Date]],tblHistory[Date],">="&tblHistory[[#This Row],[Date]]-365)-1)-Dashboard!$G$16)/(Dashboard!$H$16-Dashboard!$G$16))),0)) | N5: =IF(tblHistory[[#This Row],[Date]]-MIN(tblHistory[Date])<364,NA(),IF(ISNUMBER(tblHistory[[#This Row],[CRWV]]),MIN(1,MAX(0,((tblHistory[[#This Row],[CRWV]]/_xlfn.MAXIFS(tblHistory[CRWV],tblHistory[Date],"<="&tblHistory[[#This Row],[Date]],tblHistory[Date],">="&tblHistory[[#This Row],[Date]]-365)-1)-Dashboard!$G$17)/(Dashboard!$H$17-Dashboard!$G$17))),0)) | O5: =IF(tblHistory[[#This Row],[Date]]-MIN(tblHistory[Date])<364,NA(),IF(ISNUMBER(tblHistory[[#This Row],[BIZD]]),MIN(1,MAX(0,((tblHistory[[#This Row],[BIZD]]/_xlfn.MAXIFS(tblHistory[BIZD],tblHistory[Date],"<="&tblHistory[[#This Row],[Date]],tblHistory[Date],">="&tblHistory[[#This Row],[Date]]-365)-1)-Dashboard!$G$18)/(Dashboard!$H$18-Dashboard!$G$18))),0)) | P5: =IF(tblHistory[[#This Row],[Date]]-MIN(tblHistory[Date])<364,NA(),IF(ISNUMBER(tblHistory[[#This Row],[BKLN]]),MIN(1,MAX(0,((tblHistory[[#This Row],[BKLN]]/_xlfn.MAXIFS(tblHistory[BKLN],tblHistory[Date],"<="&tblHistory[[#This Row],[Date]],tblHistory[Date],">="&tblHistory[[#This Row],[Date]]-365)-1)-Dashboard!$G$19)/(Dashboard!$H$19-Dashboard!$G$19))),0)) | Q5: =IF(tblHistory[[#This Row],[Date]]-MIN(tblHistory[Date])<364,NA(),MIN(1,MAX(0,(IF(ISNUMBER(tblHistory[[#This Row],[HY]]),tblHistory[[#This Row],[HY]],SUMIFS(tblHistory[HY],tblHistory[Date],_xlfn.MAXIFS(tblHistory[Date],tblHistory[Date],"<"&tblHistory[[#This Row],[Date]],tblHistory[HY],"<>")))-Dashboard!$G$20)/(Dashboard!$H$20-Dashboard!$G$20)))) | R5: =(Dashboard!$C$13*tblHistory[[#This Row],[NDX S]]+Dashboard!$C$14*tblHistory[[#This Row],[SOX S]]+Dashboard!$C$15*tblHistory[[#This Row],[AIQ S]])/SUM(Dashboard!$C$13:$C$15)*100 | S5: =(Dashboard!$C$16*tblHistory[[#This Row],[ORCL S]]+Dashboard!$C$17*tblHistory[[#This Row],[CRWV S]])/SUM(Dashboard!$C$16:$C$17)*100 | T5: =(Dashboard!$C$18*tblHistory[[#This Row],[BIZD S]]+Dashboard!$C$19*tblHistory[[#This Row],[BKLN S]]+Dashboard!$C$20*tblHistory[[#This Row],[HY S]])/SUM(Dashboard!$C$18:$C$20)*100 | U5: =ROUND((Dashboard!$C$13*tblHistory[[#This Row],[NDX S]]+Dashboard!$C$14*tblHistory[[#This Row],[SOX S]]+Dashboard!$C$15*tblHistory[[#This Row],[AIQ S]]+Dashboard!$C$16*tblHistory[[#This Row],[ORCL S]]+Dashboard!$C$17*tblHistory[[#This Row],[CRWV S]]+Dashboard!$C$18*tblHistory[[#This Row],[BIZD S]]+Dashboard!$C$19*tblHistory[[#This Row],[BKLN S]]+Dashboard!$C$20*tblHistory[[#This Row],[HY S]])/SUM(Dashboard!$C$13:$C$20)*100,0) | V5: =IFERROR(--(tblHistory[[#This Row],[Score]]>=50),0) | W5: =IFERROR(--AND(tblHistory[[#This Row],[Score]]>=60,tblHistory[[#This Row],[BIZD S]]>=0.8,tblHistory[[#This Row],[BKLN S]]>=0.5),0) | X5: =IFERROR(--AND(tblHistory[[#This Row],[Score]]>=70,tblHistory[[#This Row],[SOX S]]>=0.83,tblHistory[[#This Row],[AIQ S]]>=0.8),0) | Y5: =IFERROR(--AND(tblHistory[[#This Row],[Score]]>=75,tblHistory[[#This Row],[NDX S]]=1,OR(IF(ISNUMBER(tblHistory[[#This Row],[HY]]),tblHistory[[#This Row],[HY]],SUMIFS(tblHistory[HY],tblHistory[Date],_xlfn.MAXIFS(tblHistory[Date],tblHistory[Date],"<"&tblHistory[[#This Row],[Date]],tblHistory[HY],"<>")))>=500,tblHistory[[#This Row],[BIZD S]]=1)),0) | Z5: =IFERROR(--(COUNTIFS(tblHistory[Date],">="&tblHistory[[#This Row],[Date]],tblHistory[Date],"<="&_xlfn.AGGREGATE(15,6,tblHistory[Date]/(tblHistory[Date]>=tblHistory[[#This Row],[Date]]),5),tblHistory[L1],1)=5),0) | AA5: =IFERROR(--(COUNTIFS(tblHistory[Date],">="&tblHistory[[#This Row],[Date]],tblHistory[Date],"<="&_xlfn.AGGREGATE(15,6,tblHistory[Date]/(tblHistory[Date]>=tblHistory[[#This Row],[Date]]),5),tblHistory[L2],1)=5),0) | AB5: =IFERROR(--(COUNTIFS(tblHistory[Date],">="&tblHistory[[#This Row],[Date]],tblHistory[Date],"<="&_xlfn.AGGREGATE(15,6,tblHistory[Date]/(tblHistory[Date]>=tblHistory[[#This Row],[Date]]),5),tblHistory[L3],1)=5),0) | AC5: =IFERROR(--(COUNTIFS(tblHistory[Date],">="&tblHistory[[#This Row],[Date]],tblHistory[Date],"<="&_xlfn.AGGREGATE(15,6,tblHistory[Date]/(tblHistory[Date]>=tblHistory[[#This Row],[Date]]),5),tblHistory[L4],1)=5),0)
A6: 46308 | B6: 25181.51 | C6: 8718.71 | D6: 39.11 | E6: 197.87 | F6: 34.57 | G6: 16.27 | H6: 20.77 | I6: 400 | J6: =IF(tblHistory[[#This Row],[Date]]-MIN(tblHistory[Date])<364,NA(),IF(ISNUMBER(tblHistory[[#This Row],[NDX]]),MIN(1,MAX(0,((tblHistory[[#This Row],[NDX]]/_xlfn.MAXIFS(tblHistory[NDX],tblHistory[Date],"<="&tblHistory[[#This Row],[Date]],tblHistory[Date],">="&tblHistory[[#This Row],[Date]]-365)-1)-Dashboard!$G$13)/(Dashboard!$H$13-Dashboard!$G$13))),0)) | K6: =IF(tblHistory[[#This Row],[Date]]-MIN(tblHistory[Date])<364,NA(),IF(ISNUMBER(tblHistory[[#This Row],[SOX]]),MIN(1,MAX(0,((tblHistory[[#This Row],[SOX]]/_xlfn.MAXIFS(tblHistory[SOX],tblHistory[Date],"<="&tblHistory[[#This Row],[Date]],tblHistory[Date],">="&tblHistory[[#This Row],[Date]]-365)-1)-Dashboard!$G$14)/(Dashboard!$H$14-Dashboard!$G$14))),0)) | L6: =IF(tblHistory[[#This Row],[Date]]-MIN(tblHistory[Date])<364,NA(),IF(ISNUMBER(tblHistory[[#This Row],[AIQ]]),MIN(1,MAX(0,((tblHistory[[#This Row],[AIQ]]/_xlfn.MAXIFS(tblHistory[AIQ],tblHistory[Date],"<="&tblHistory[[#This Row],[Date]],tblHistory[Date],">="&tblHistory[[#This Row],[Date]]-365)-1)-Dashboard!$G$15)/(Dashboard!$H$15-Dashboard!$G$15))),0)) | M6: =IF(tblHistory[[#This Row],[Date]]-MIN(tblHistory[Date])<364,NA(),IF(ISNUMBER(tblHistory[[#This Row],[ORCL]]),MIN(1,MAX(0,((tblHistory[[#This Row],[ORCL]]/_xlfn.MAXIFS(tblHistory[ORCL],tblHistory[Date],"<="&tblHistory[[#This Row],[Date]],tblHistory[Date],">="&tblHistory[[#This Row],[Date]]-365)-1)-Dashboard!$G$16)/(Dashboard!$H$16-Dashboard!$G$16))),0)) | N6: =IF(tblHistory[[#This Row],[Date]]-MIN(tblHistory[Date])<364,NA(),IF(ISNUMBER(tblHistory[[#This Row],[CRWV]]),MIN(1,MAX(0,((tblHistory[[#This Row],[CRWV]]/_xlfn.MAXIFS(tblHistory[CRWV],tblHistory[Date],"<="&tblHistory[[#This Row],[Date]],tblHistory[Date],">="&tblHistory[[#This Row],[Date]]-365)-1)-Dashboard!$G$17)/(Dashboard!$H$17-Dashboard!$G$17))),0)) | O6: =IF(tblHistory[[#This Row],[Date]]-MIN(tblHistory[Date])<364,NA(),IF(ISNUMBER(tblHistory[[#This Row],[BIZD]]),MIN(1,MAX(0,((tblHistory[[#This Row],[BIZD]]/_xlfn.MAXIFS(tblHistory[BIZD],tblHistory[Date],"<="&tblHistory[[#This Row],[Date]],tblHistory[Date],">="&tblHistory[[#This Row],[Date]]-365)-1)-Dashboard!$G$18)/(Dashboard!$H$18-Dashboard!$G$18))),0)) | P6: =IF(tblHistory[[#This Row],[Date]]-MIN(tblHistory[Date])<364,NA(),IF(ISNUMBER(tblHistory[[#This Row],[BKLN]]),MIN(1,MAX(0,((tblHistory[[#This Row],[BKLN]]/_xlfn.MAXIFS(tblHistory[BKLN],tblHistory[Date],"<="&tblHistory[[#This Row],[Date]],tblHistory[Date],">="&tblHistory[[#This Row],[Date]]-365)-1)-Dashboard!$G$19)/(Dashboard!$H$19-Dashboard!$G$19))),0)) | Q6: =IF(tblHistory[[#This Row],[Date]]-MIN(tblHistory[Date])<364,NA(),MIN(1,MAX(0,(IF(ISNUMBER(tblHistory[[#This Row],[HY]]),tblHistory[[#This Row],[HY]],SUMIFS(tblHistory[HY],tblHistory[Date],_xlfn.MAXIFS(tblHistory[Date],tblHistory[Date],"<"&tblHistory[[#This Row],[Date]],tblHistory[HY],"<>")))-Dashboard!$G$20)/(Dashboard!$H$20-Dashboard!$G$20)))) | R6: =(Dashboard!$C$13*tblHistory[[#This Row],[NDX S]]+Dashboard!$C$14*tblHistory[[#This Row],[SOX S]]+Dashboard!$C$15*tblHistory[[#This Row],[AIQ S]])/SUM(Dashboard!$C$13:$C$15)*100 | S6: =(Dashboard!$C$16*tblHistory[[#This Row],[ORCL S]]+Dashboard!$C$17*tblHistory[[#This Row],[CRWV S]])/SUM(Dashboard!$C$16:$C$17)*100 | T6: =(Dashboard!$C$18*tblHistory[[#This Row],[BIZD S]]+Dashboard!$C$19*tblHistory[[#This Row],[BKLN S]]+Dashboard!$C$20*tblHistory[[#This Row],[HY S]])/SUM(Dashboard!$C$18:$C$20)*100 | U6: =ROUND((Dashboard!$C$13*tblHistory[[#This Row],[NDX S]]+Dashboard!$C$14*tblHistory[[#This Row],[SOX S]]+Dashboard!$C$15*tblHistory[[#This Row],[AIQ S]]+Dashboard!$C$16*tblHistory[[#This Row],[ORCL S]]+Dashboard!$C$17*tblHistory[[#This Row],[CRWV S]]+Dashboard!$C$18*tblHistory[[#This Row],[BIZD S]]+Dashboard!$C$19*tblHistory[[#This Row],[BKLN S]]+Dashboard!$C$20*tblHistory[[#This Row],[HY S]])/SUM(Dashboard!$C$13:$C$20)*100,0) | V6: =IFERROR(--(tblHistory[[#This Row],[Score]]>=50),0) | W6: =IFERROR(--AND(tblHistory[[#This Row],[Score]]>=60,tblHistory[[#This Row],[BIZD S]]>=0.8,tblHistory[[#This Row],[BKLN S]]>=0.5),0) | X6: =IFERROR(--AND(tblHistory[[#This Row],[Score]]>=70,tblHistory[[#This Row],[SOX S]]>=0.83,tblHistory[[#This Row],[AIQ S]]>=0.8),0) | Y6: =IFERROR(--AND(tblHistory[[#This Row],[Score]]>=75,tblHistory[[#This Row],[NDX S]]=1,OR(IF(ISNUMBER(tblHistory[[#This Row],[HY]]),tblHistory[[#This Row],[HY]],SUMIFS(tblHistory[HY],tblHistory[Date],_xlfn.MAXIFS(tblHistory[Date],tblHistory[Date],"<"&tblHistory[[#This Row],[Date]],tblHistory[HY],"<>")))>=500,tblHistory[[#This Row],[BIZD S]]=1)),0) | Z6: =IFERROR(--(COUNTIFS(tblHistory[Date],">="&tblHistory[[#This Row],[Date]],tblHistory[Date],"<="&_xlfn.AGGREGATE(15,6,tblHistory[Date]/(tblHistory[Date]>=tblHistory[[#This Row],[Date]]),5),tblHistory[L1],1)=5),0) | AA6: =IFERROR(--(COUNTIFS(tblHistory[Date],">="&tblHistory[[#This Row],[Date]],tblHistory[Date],"<="&_xlfn.AGGREGATE(15,6,tblHistory[Date]/(tblHistory[Date]>=tblHistory[[#This Row],[Date]]),5),tblHistory[L2],1)=5),0) | AB6: =IFERROR(--(COUNTIFS(tblHistory[Date],">="&tblHistory[[#This Row],[Date]],tblHistory[Date],"<="&_xlfn.AGGREGATE(15,6,tblHistory[Date]/(tblHistory[Date]>=tblHistory[[#This Row],[Date]]),5),tblHistory[L3],1)=5),0) | AC6: =IFERROR(--(COUNTIFS(tblHistory[Date],">="&tblHistory[[#This Row],[Date]],tblHistory[Date],"<="&_xlfn.AGGREGATE(15,6,tblHistory[Date]/(tblHistory[Date]>=tblHistory[[#This Row],[Date]]),5),tblHistory[L4],1)=5),0)
A7: 46307 | B7: 24926.01 | C7: 8940.89 | D7: 39.22 | E7: 199.65 | F7: 37.23 | G7: 16.42 | H7: 20.8 | I7: 395 | J7: =IF(tblHistory[[#This Row],[Date]]-MIN(tblHistory[Date])<364,NA(),IF(ISNUMBER(tblHistory[[#This Row],[NDX]]),MIN(1,MAX(0,((tblHistory[[#This Row],[NDX]]/_xlfn.MAXIFS(tblHistory[NDX],tblHistory[Date],"<="&tblHistory[[#This Row],[Date]],tblHistory[Date],">="&tblHistory[[#This Row],[Date]]-365)-1)-Dashboard!$G$13)/(Dashboard!$H$13-Dashboard!$G$13))),0)) | K7: =IF(tblHistory[[#This Row],[Date]]-MIN(tblHistory[Date])<364,NA(),IF(ISNUMBER(tblHistory[[#This Row],[SOX]]),MIN(1,MAX(0,((tblHistory[[#This Row],[SOX]]/_xlfn.MAXIFS(tblHistory[SOX],tblHistory[Date],"<="&tblHistory[[#This Row],[Date]],tblHistory[Date],">="&tblHistory[[#This Row],[Date]]-365)-1)-Dashboard!$G$14)/(Dashboard!$H$14-Dashboard!$G$14))),0)) | L7: =IF(tblHistory[[#This Row],[Date]]-MIN(tblHistory[Date])<364,NA(),IF(ISNUMBER(tblHistory[[#This Row],[AIQ]]),MIN(1,MAX(0,((tblHistory[[#This Row],[AIQ]]/_xlfn.MAXIFS(tblHistory[AIQ],tblHistory[Date],"<="&tblHistory[[#This Row],[Date]],tblHistory[Date],">="&tblHistory[[#This Row],[Date]]-365)-1)-Dashboard!$G$15)/(Dashboard!$H$15-Dashboard!$G$15))),0)) | M7: =IF(tblHistory[[#This Row],[Date]]-MIN(tblHistory[Date])<364,NA(),IF(ISNUMBER(tblHistory[[#This Row],[ORCL]]),MIN(1,MAX(0,((tblHistory[[#This Row],[ORCL]]/_xlfn.MAXIFS(tblHistory[ORCL],tblHistory[Date],"<="&tblHistory[[#This Row],[Date]],tblHistory[Date],">="&tblHistory[[#This Row],[Date]]-365)-1)-Dashboard!$G$16)/(Dashboard!$H$16-Dashboard!$G$16))),0)) | N7: =IF(tblHistory[[#This Row],[Date]]-MIN(tblHistory[Date])<364,NA(),IF(ISNUMBER(tblHistory[[#This Row],[CRWV]]),MIN(1,MAX(0,((tblHistory[[#This Row],[CRWV]]/_xlfn.MAXIFS(tblHistory[CRWV],tblHistory[Date],"<="&tblHistory[[#This Row],[Date]],tblHistory[Date],">="&tblHistory[[#This Row],[Date]]-365)-1)-Dashboard!$G$17)/(Dashboard!$H$17-Dashboard!$G$17))),0)) | O7: =IF(tblHistory[[#This Row],[Date]]-MIN(tblHistory[Date])<364,NA(),IF(ISNUMBER(tblHistory[[#This Row],[BIZD]]),MIN(1,MAX(0,((tblHistory[[#This Row],[BIZD]]/_xlfn.MAXIFS(tblHistory[BIZD],tblHistory[Date],"<="&tblHistory[[#This Row],[Date]],tblHistory[Date],">="&tblHistory[[#This Row],[Date]]-365)-1)-Dashboard!$G$18)/(Dashboard!$H$18-Dashboard!$G$18))),0)) | P7: =IF(tblHistory[[#This Row],[Date]]-MIN(tblHistory[Date])<364,NA(),IF(ISNUMBER(tblHistory[[#This Row],[BKLN]]),MIN(1,MAX(0,((tblHistory[[#This Row],[BKLN]]/_xlfn.MAXIFS(tblHistory[BKLN],tblHistory[Date],"<="&tblHistory[[#This Row],[Date]],tblHistory[Date],">="&tblHistory[[#This Row],[Date]]-365)-1)-Dashboard!$G$19)/(Dashboard!$H$19-Dashboard!$G$19))),0)) | Q7: =IF(tblHistory[[#This Row],[Date]]-MIN(tblHistory[Date])<364,NA(),MIN(1,MAX(0,(IF(ISNUMBER(tblHistory[[#This Row],[HY]]),tblHistory[[#This Row],[HY]],SUMIFS(tblHistory[HY],tblHistory[Date],_xlfn.MAXIFS(tblHistory[Date],tblHistory[Date],"<"&tblHistory[[#This Row],[Date]],tblHistory[HY],"<>")))-Dashboard!$G$20)/(Dashboard!$H$20-Dashboard!$G$20)))) | R7: =(Dashboard!$C$13*tblHistory[[#This Row],[NDX S]]+Dashboard!$C$14*tblHistory[[#This Row],[SOX S]]+Dashboard!$C$15*tblHistory[[#This Row],[AIQ S]])/SUM(Dashboard!$C$13:$C$15)*100 | S7: =(Dashboard!$C$16*tblHistory[[#This Row],[ORCL S]]+Dashboard!$C$17*tblHistory[[#This Row],[CRWV S]])/SUM(Dashboard!$C$16:$C$17)*100 | T7: =(Dashboard!$C$18*tblHistory[[#This Row],[BIZD S]]+Dashboard!$C$19*tblHistory[[#This Row],[BKLN S]]+Dashboard!$C$20*tblHistory[[#This Row],[HY S]])/SUM(Dashboard!$C$18:$C$20)*100 | U7: =ROUND((Dashboard!$C$13*tblHistory[[#This Row],[NDX S]]+Dashboard!$C$14*tblHistory[[#This Row],[SOX S]]+Dashboard!$C$15*tblHistory[[#This Row],[AIQ S]]+Dashboard!$C$16*tblHistory[[#This Row],[ORCL S]]+Dashboard!$C$17*tblHistory[[#This Row],[CRWV S]]+Dashboard!$C$18*tblHistory[[#This Row],[BIZD S]]+Dashboard!$C$19*tblHistory[[#This Row],[BKLN S]]+Dashboard!$C$20*tblHistory[[#This Row],[HY S]])/SUM(Dashboard!$C$13:$C$20)*100,0) | V7: =IFERROR(--(tblHistory[[#This Row],[Score]]>=50),0) | W7: =IFERROR(--AND(tblHistory[[#This Row],[Score]]>=60,tblHistory[[#This Row],[BIZD S]]>=0.8,tblHistory[[#This Row],[BKLN S]]>=0.5),0) | X7: =IFERROR(--AND(tblHistory[[#This Row],[Score]]>=70,tblHistory[[#This Row],[SOX S]]>=0.83,tblHistory[[#This Row],[AIQ S]]>=0.8),0) | Y7: =IFERROR(--AND(tblHistory[[#This Row],[Score]]>=75,tblHistory[[#This Row],[NDX S]]=1,OR(IF(ISNUMBER(tblHistory[[#This Row],[HY]]),tblHistory[[#This Row],[HY]],SUMIFS(tblHistory[HY],tblHistory[Date],_xlfn.MAXIFS(tblHistory[Date],tblHistory[Date],"<"&tblHistory[[#This Row],[Date]],tblHistory[HY],"<>")))>=500,tblHistory[[#This Row],[BIZD S]]=1)),0) | Z7: =IFERROR(--(COUNTIFS(tblHistory[Date],">="&tblHistory[[#This Row],[Date]],tblHistory[Date],"<="&_xlfn.AGGREGATE(15,6,tblHistory[Date]/(tblHistory[Date]>=tblHistory[[#This Row],[Date]]),5),tblHistory[L1],1)=5),0) | AA7: =IFERROR(--(COUNTIFS(tblHistory[Date],">="&tblHistory[[#This Row],[Date]],tblHistory[Date],"<="&_xlfn.AGGREGATE(15,6,tblHistory[Date]/(tblHistory[Date]>=tblHistory[[#This Row],[Date]]),5),tblHistory[L2],1)=5),0) | AB7: =IFERROR(--(COUNTIFS(tblHistory[Date],">="&tblHistory[[#This Row],[Date]],tblHistory[Date],"<="&_xlfn.AGGREGATE(15,6,tblHistory[Date]/(tblHistory[Date]>=tblHistory[[#This Row],[Date]]),5),tblHistory[L3],1)=5),0) | AC7: =IFERROR(--(COUNTIFS(tblHistory[Date],">="&tblHistory[[#This Row],[Date]],tblHistory[Date],"<="&_xlfn.AGGREGATE(15,6,tblHistory[Date]/(tblHistory[Date]>=tblHistory[[#This Row],[Date]]),5),tblHistory[L4],1)=5),0)
A8: 46304 | B8: 24969.32 | C8: 9311.97 | D8: 39.63 | E8: 212.19 | F8: 37.35 | G8: 16.38 | H8: 20.82 | I8: 406 | J8: =IF(tblHistory[[#This Row],[Date]]-MIN(tblHistory[Date])<364,NA(),IF(ISNUMBER(tblHistory[[#This Row],[NDX]]),MIN(1,MAX(0,((tblHistory[[#This Row],[NDX]]/_xlfn.MAXIFS(tblHistory[NDX],tblHistory[Date],"<="&tblHistory[[#This Row],[Date]],tblHistory[Date],">="&tblHistory[[#This Row],[Date]]-365)-1)-Dashboard!$G$13)/(Dashboard!$H$13-Dashboard!$G$13))),0)) | K8: =IF(tblHistory[[#This Row],[Date]]-MIN(tblHistory[Date])<364,NA(),IF(ISNUMBER(tblHistory[[#This Row],[SOX]]),MIN(1,MAX(0,((tblHistory[[#This Row],[SOX]]/_xlfn.MAXIFS(tblHistory[SOX],tblHistory[Date],"<="&tblHistory[[#This Row],[Date]],tblHistory[Date],">="&tblHistory[[#This Row],[Date]]-365)-1)-Dashboard!$G$14)/(Dashboard!$H$14-Dashboard!$G$14))),0)) | L8: =IF(tblHistory[[#This Row],[Date]]-MIN(tblHistory[Date])<364,NA(),IF(ISNUMBER(tblHistory[[#This Row],[AIQ]]),MIN(1,MAX(0,((tblHistory[[#This Row],[AIQ]]/_xlfn.MAXIFS(tblHistory[AIQ],tblHistory[Date],"<="&tblHistory[[#This Row],[Date]],tblHistory[Date],">="&tblHistory[[#This Row],[Date]]-365)-1)-Dashboard!$G$15)/(Dashboard!$H$15-Dashboard!$G$15))),0)) | M8: =IF(tblHistory[[#This Row],[Date]]-MIN(tblHistory[Date])<364,NA(),IF(ISNUMBER(tblHistory[[#This Row],[ORCL]]),MIN(1,MAX(0,((tblHistory[[#This Row],[ORCL]]/_xlfn.MAXIFS(tblHistory[ORCL],tblHistory[Date],"<="&tblHistory[[#This Row],[Date]],tblHistory[Date],">="&tblHistory[[#This Row],[Date]]-365)-1)-Dashboard!$G$16)/(Dashboard!$H$16-Dashboard!$G$16))),0)) | N8: =IF(tblHistory[[#This Row],[Date]]-MIN(tblHistory[Date])<364,NA(),IF(ISNUMBER(tblHistory[[#This Row],[CRWV]]),MIN(1,MAX(0,((tblHistory[[#This Row],[CRWV]]/_xlfn.MAXIFS(tblHistory[CRWV],tblHistory[Date],"<="&tblHistory[[#This Row],[Date]],tblHistory[Date],">="&tblHistory[[#This Row],[Date]]-365)-1)-Dashboard!$G$17)/(Dashboard!$H$17-Dashboard!$G$17))),0)) | O8: =IF(tblHistory[[#This Row],[Date]]-MIN(tblHistory[Date])<364,NA(),IF(ISNUMBER(tblHistory[[#This Row],[BIZD]]),MIN(1,MAX(0,((tblHistory[[#This Row],[BIZD]]/_xlfn.MAXIFS(tblHistory[BIZD],tblHistory[Date],"<="&tblHistory[[#This Row],[Date]],tblHistory[Date],">="&tblHistory[[#This Row],[Date]]-365)-1)-Dashboard!$G$18)/(Dashboard!$H$18-Dashboard!$G$18))),0)) | P8: =IF(tblHistory[[#This Row],[Date]]-MIN(tblHistory[Date])<364,NA(),IF(ISNUMBER(tblHistory[[#This Row],[BKLN]]),MIN(1,MAX(0,((tblHistory[[#This Row],[BKLN]]/_xlfn.MAXIFS(tblHistory[BKLN],tblHistory[Date],"<="&tblHistory[[#This Row],[Date]],tblHistory[Date],">="&tblHistory[[#This Row],[Date]]-365)-1)-Dashboard!$G$19)/(Dashboard!$H$19-Dashboard!$G$19))),0)) | Q8: =IF(tblHistory[[#This Row],[Date]]-MIN(tblHistory[Date])<364,NA(),MIN(1,MAX(0,(IF(ISNUMBER(tblHistory[[#This Row],[HY]]),tblHistory[[#This Row],[HY]],SUMIFS(tblHistory[HY],tblHistory[Date],_xlfn.MAXIFS(tblHistory[Date],tblHistory[Date],"<"&tblHistory[[#This Row],[Date]],tblHistory[HY],"<>")))-Dashboard!$G$20)/(Dashboard!$H$20-Dashboard!$G$20)))) | R8: =(Dashboard!$C$13*tblHistory[[#This Row],[NDX S]]+Dashboard!$C$14*tblHistory[[#This Row],[SOX S]]+Dashboard!$C$15*tblHistory[[#This Row],[AIQ S]])/SUM(Dashboard!$C$13:$C$15)*100 | S8: =(Dashboard!$C$16*tblHistory[[#This Row],[ORCL S]]+Dashboard!$C$17*tblHistory[[#This Row],[CRWV S]])/SUM(Dashboard!$C$16:$C$17)*100 | T8: =(Dashboard!$C$18*tblHistory[[#This Row],[BIZD S]]+Dashboard!$C$19*tblHistory[[#This Row],[BKLN S]]+Dashboard!$C$20*tblHistory[[#This Row],[HY S]])/SUM(Dashboard!$C$18:$C$20)*100 | U8: =ROUND((Dashboard!$C$13*tblHistory[[#This Row],[NDX S]]+Dashboard!$C$14*tblHistory[[#This Row],[SOX S]]+Dashboard!$C$15*tblHistory[[#This Row],[AIQ S]]+Dashboard!$C$16*tblHistory[[#This Row],[ORCL S]]+Dashboard!$C$17*tblHistory[[#This Row],[CRWV S]]+Dashboard!$C$18*tblHistory[[#This Row],[BIZD S]]+Dashboard!$C$19*tblHistory[[#This Row],[BKLN S]]+Dashboard!$C$20*tblHistory[[#This Row],[HY S]])/SUM(Dashboard!$C$13:$C$20)*100,0) | V8: =IFERROR(--(tblHistory[[#This Row],[Score]]>=50),0) | W8: =IFERROR(--AND(tblHistory[[#This Row],[Score]]>=60,tblHistory[[#This Row],[BIZD S]]>=0.8,tblHistory[[#This Row],[BKLN S]]>=0.5),0) | X8: =IFERROR(--AND(tblHistory[[#This Row],[Score]]>=70,tblHistory[[#This Row],[SOX S]]>=0.83,tblHistory[[#This Row],[AIQ S]]>=0.8),0) | Y8: =IFERROR(--AND(tblHistory[[#This Row],[Score]]>=75,tblHistory[[#This Row],[NDX S]]=1,OR(IF(ISNUMBER(tblHistory[[#This Row],[HY]]),tblHistory[[#This Row],[HY]],SUMIFS(tblHistory[HY],tblHistory[Date],_xlfn.MAXIFS(tblHistory[Date],tblHistory[Date],"<"&tblHistory[[#This Row],[Date]],tblHistory[HY],"<>")))>=500,tblHistory[[#This Row],[BIZD S]]=1)),0) | Z8: =IFERROR(--(COUNTIFS(tblHistory[Date],">="&tblHistory[[#This Row],[Date]],tblHistory[Date],"<="&_xlfn.AGGREGATE(15,6,tblHistory[Date]/(tblHistory[Date]>=tblHistory[[#This Row],[Date]]),5),tblHistory[L1],1)=5),0) | AA8: =IFERROR(--(COUNTIFS(tblHistory[Date],">="&tblHistory[[#This Row],[Date]],tblHistory[Date],"<="&_xlfn.AGGREGATE(15,6,tblHistory[Date]/(tblHistory[Date]>=tblHistory[[#This Row],[Date]]),5),tblHistory[L2],1)=5),0) | AB8: =IFERROR(--(COUNTIFS(tblHistory[Date],">="&tblHistory[[#This Row],[Date]],tblHistory[Date],"<="&_xlfn.AGGREGATE(15,6,tblHistory[Date]/(tblHistory[Date]>=tblHistory[[#This Row],[Date]]),5),tblHistory[L3],1)=5),0) | AC8: =IFERROR(--(COUNTIFS(tblHistory[Date],">="&tblHistory[[#This Row],[Date]],tblHistory[Date],"<="&_xlfn.AGGREGATE(15,6,tblHistory[Date]/(tblHistory[Date]>=tblHistory[[#This Row],[Date]]),5),tblHistory[L4],1)=5),0)
A9: 46303 | B9: 24720.26 | C9: 9533.68 | D9: 39.78 | E9: 219.99 | F9: 37.93 | G9: 16.42 | H9: 20.84 | I9: 408 | J9: =IF(tblHistory[[#This Row],[Date]]-MIN(tblHistory[Date])<364,NA(),IF(ISNUMBER(tblHistory[[#This Row],[NDX]]),MIN(1,MAX(0,((tblHistory[[#This Row],[NDX]]/_xlfn.MAXIFS(tblHistory[NDX],tblHistory[Date],"<="&tblHistory[[#This Row],[Date]],tblHistory[Date],">="&tblHistory[[#This Row],[Date]]-365)-1)-Dashboard!$G$13)/(Dashboard!$H$13-Dashboard!$G$13))),0)) | K9: =IF(tblHistory[[#This Row],[Date]]-MIN(tblHistory[Date])<364,NA(),IF(ISNUMBER(tblHistory[[#This Row],[SOX]]),MIN(1,MAX(0,((tblHistory[[#This Row],[SOX]]/_xlfn.MAXIFS(tblHistory[SOX],tblHistory[Date],"<="&tblHistory[[#This Row],[Date]],tblHistory[Date],">="&tblHistory[[#This Row],[Date]]-365)-1)-Dashboard!$G$14)/(Dashboard!$H$14-Dashboard!$G$14))),0)) | L9: =IF(tblHistory[[#This Row],[Date]]-MIN(tblHistory[Date])<364,NA(),IF(ISNUMBER(tblHistory[[#This Row],[AIQ]]),MIN(1,MAX(0,((tblHistory[[#This Row],[AIQ]]/_xlfn.MAXIFS(tblHistory[AIQ],tblHistory[Date],"<="&tblHistory[[#This Row],[Date]],tblHistory[Date],">="&tblHistory[[#This Row],[Date]]-365)-1)-Dashboard!$G$15)/(Dashboard!$H$15-Dashboard!$G$15))),0)) | M9: =IF(tblHistory[[#This Row],[Date]]-MIN(tblHistory[Date])<364,NA(),IF(ISNUMBER(tblHistory[[#This Row],[ORCL]]),MIN(1,MAX(0,((tblHistory[[#This Row],[ORCL]]/_xlfn.MAXIFS(tblHistory[ORCL],tblHistory[Date],"<="&tblHistory[[#This Row],[Date]],tblHistory[Date],">="&tblHistory[[#This Row],[Date]]-365)-1)-Dashboard!$G$16)/(Dashboard!$H$16-Dashboard!$G$16))),0)) | N9: =IF(tblHistory[[#This Row],[Date]]-MIN(tblHistory[Date])<364,NA(),IF(ISNUMBER(tblHistory[[#This Row],[CRWV]]),MIN(1,MAX(0,((tblHistory[[#This Row],[CRWV]]/_xlfn.MAXIFS(tblHistory[CRWV],tblHistory[Date],"<="&tblHistory[[#This Row],[Date]],tblHistory[Date],">="&tblHistory[[#This Row],[Date]]-365)-1)-Dashboard!$G$17)/(Dashboard!$H$17-Dashboard!$G$17))),0)) | O9: =IF(tblHistory[[#This Row],[Date]]-MIN(tblHistory[Date])<364,NA(),IF(ISNUMBER(tblHistory[[#This Row],[BIZD]]),MIN(1,MAX(0,((tblHistory[[#This Row],[BIZD]]/_xlfn.MAXIFS(tblHistory[BIZD],tblHistory[Date],"<="&tblHistory[[#This Row],[Date]],tblHistory[Date],">="&tblHistory[[#This Row],[Date]]-365)-1)-Dashboard!$G$18)/(Dashboard!$H$18-Dashboard!$G$18))),0)) | P9: =IF(tblHistory[[#This Row],[Date]]-MIN(tblHistory[Date])<364,NA(),IF(ISNUMBER(tblHistory[[#This Row],[BKLN]]),MIN(1,MAX(0,((tblHistory[[#This Row],[BKLN]]/_xlfn.MAXIFS(tblHistory[BKLN],tblHistory[Date],"<="&tblHistory[[#This Row],[Date]],tblHistory[Date],">="&tblHistory[[#This Row],[Date]]-365)-1)-Dashboard!$G$19)/(Dashboard!$H$19-Dashboard!$G$19))),0)) | Q9: =IF(tblHistory[[#This Row],[Date]]-MIN(tblHistory[Date])<364,NA(),MIN(1,MAX(0,(IF(ISNUMBER(tblHistory[[#This Row],[HY]]),tblHistory[[#This Row],[HY]],SUMIFS(tblHistory[HY],tblHistory[Date],_xlfn.MAXIFS(tblHistory[Date],tblHistory[Date],"<"&tblHistory[[#This Row],[Date]],tblHistory[HY],"<>")))-Dashboard!$G$20)/(Dashboard!$H$20-Dashboard!$G$20)))) | R9: =(Dashboard!$C$13*tblHistory[[#This Row],[NDX S]]+Dashboard!$C$14*tblHistory[[#This Row],[SOX S]]+Dashboard!$C$15*tblHistory[[#This Row],[AIQ S]])/SUM(Dashboard!$C$13:$C$15)*100 | S9: =(Dashboard!$C$16*tblHistory[[#This Row],[ORCL S]]+Dashboard!$C$17*tblHistory[[#This Row],[CRWV S]])/SUM(Dashboard!$C$16:$C$17)*100 | T9: =(Dashboard!$C$18*tblHistory[[#This Row],[BIZD S]]+Dashboard!$C$19*tblHistory[[#This Row],[BKLN S]]+Dashboard!$C$20*tblHistory[[#This Row],[HY S]])/SUM(Dashboard!$C$18:$C$20)*100 | U9: =ROUND((Dashboard!$C$13*tblHistory[[#This Row],[NDX S]]+Dashboard!$C$14*tblHistory[[#This Row],[SOX S]]+Dashboard!$C$15*tblHistory[[#This Row],[AIQ S]]+Dashboard!$C$16*tblHistory[[#This Row],[ORCL S]]+Dashboard!$C$17*tblHistory[[#This Row],[CRWV S]]+Dashboard!$C$18*tblHistory[[#This Row],[BIZD S]]+Dashboard!$C$19*tblHistory[[#This Row],[BKLN S]]+Dashboard!$C$20*tblHistory[[#This Row],[HY S]])/SUM(Dashboard!$C$13:$C$20)*100,0) | V9: =IFERROR(--(tblHistory[[#This Row],[Score]]>=50),0) | W9: =IFERROR(--AND(tblHistory[[#This Row],[Score]]>=60,tblHistory[[#This Row],[BIZD S]]>=0.8,tblHistory[[#This Row],[BKLN S]]>=0.5),0) | X9: =IFERROR(--AND(tblHistory[[#This Row],[Score]]>=70,tblHistory[[#This Row],[SOX S]]>=0.83,tblHistory[[#This Row],[AIQ S]]>=0.8),0) | Y9: =IFERROR(--AND(tblHistory[[#This Row],[Score]]>=75,tblHistory[[#This Row],[NDX S]]=1,OR(IF(ISNUMBER(tblHistory[[#This Row],[HY]]),tblHistory[[#This Row],[HY]],SUMIFS(tblHistory[HY],tblHistory[Date],_xlfn.MAXIFS(tblHistory[Date],tblHistory[Date],"<"&tblHistory[[#This Row],[Date]],tblHistory[HY],"<>")))>=500,tblHistory[[#This Row],[BIZD S]]=1)),0) | Z9: =IFERROR(--(COUNTIFS(tblHistory[Date],">="&tblHistory[[#This Row],[Date]],tblHistory[Date],"<="&_xlfn.AGGREGATE(15,6,tblHistory[Date]/(tblHistory[Date]>=tblHistory[[#This Row],[Date]]),5),tblHistory[L1],1)=5),0) | AA9: =IFERROR(--(COUNTIFS(tblHistory[Date],">="&tblHistory[[#This Row],[Date]],tblHistory[Date],"<="&_xlfn.AGGREGATE(15,6,tblHistory[Date]/(tblHistory[Date]>=tblHistory[[#This Row],[Date]]),5),tblHistory[L2],1)=5),0) | AB9: =IFERROR(--(COUNTIFS(tblHistory[Date],">="&tblHistory[[#This Row],[Date]],tblHistory[Date],"<="&_xlfn.AGGREGATE(15,6,tblHistory[Date]/(tblHistory[Date]>=tblHistory[[#This Row],[Date]]),5),tblHistory[L3],1)=5),0) | AC9: =IFERROR(--(COUNTIFS(tblHistory[Date],">="&tblHistory[[#This Row],[Date]],tblHistory[Date],"<="&_xlfn.AGGREGATE(15,6,tblHistory[Date]/(tblHistory[Date]>=tblHistory[[#This Row],[Date]]),5),tblHistory[L4],1)=5),0)
A10: 46302 | B10: 24895.24 | C10: 9432.52 | D10: 40.46 | E10: 221.54 | F10: 36.23 | G10: 16.28 | H10: 20.89 | I10: 402 | J10: =IF(tblHistory[[#This Row],[Date]]-MIN(tblHistory[Date])<364,NA(),IF(ISNUMBER(tblHistory[[#This Row],[NDX]]),MIN(1,MAX(0,((tblHistory[[#This Row],[NDX]]/_xlfn.MAXIFS(tblHistory[NDX],tblHistory[Date],"<="&tblHistory[[#This Row],[Date]],tblHistory[Date],">="&tblHistory[[#This Row],[Date]]-365)-1)-Dashboard!$G$13)/(Dashboard!$H$13-Dashboard!$G$13))),0)) | K10: =IF(tblHistory[[#This Row],[Date]]-MIN(tblHistory[Date])<364,NA(),IF(ISNUMBER(tblHistory[[#This Row],[SOX]]),MIN(1,MAX(0,((tblHistory[[#This Row],[SOX]]/_xlfn.MAXIFS(tblHistory[SOX],tblHistory[Date],"<="&tblHistory[[#This Row],[Date]],tblHistory[Date],">="&tblHistory[[#This Row],[Date]]-365)-1)-Dashboard!$G$14)/(Dashboard!$H$14-Dashboard!$G$14))),0)) | L10: =IF(tblHistory[[#This Row],[Date]]-MIN(tblHistory[Date])<364,NA(),IF(ISNUMBER(tblHistory[[#This Row],[AIQ]]),MIN(1,MAX(0,((tblHistory[[#This Row],[AIQ]]/_xlfn.MAXIFS(tblHistory[AIQ],tblHistory[Date],"<="&tblHistory[[#This Row],[Date]],tblHistory[Date],">="&tblHistory[[#This Row],[Date]]-365)-1)-Dashboard!$G$15)/(Dashboard!$H$15-Dashboard!$G$15))),0)) | M10: =IF(tblHistory[[#This Row],[Date]]-MIN(tblHistory[Date])<364,NA(),IF(ISNUMBER(tblHistory[[#This Row],[ORCL]]),MIN(1,MAX(0,((tblHistory[[#This Row],[ORCL]]/_xlfn.MAXIFS(tblHistory[ORCL],tblHistory[Date],"<="&tblHistory[[#This Row],[Date]],tblHistory[Date],">="&tblHistory[[#This Row],[Date]]-365)-1)-Dashboard!$G$16)/(Dashboard!$H$16-Dashboard!$G$16))),0)) | N10: =IF(tblHistory[[#This Row],[Date]]-MIN(tblHistory[Date])<364,NA(),IF(ISNUMBER(tblHistory[[#This Row],[CRWV]]),MIN(1,MAX(0,((tblHistory[[#This Row],[CRWV]]/_xlfn.MAXIFS(tblHistory[CRWV],tblHistory[Date],"<="&tblHistory[[#This Row],[Date]],tblHistory[Date],">="&tblHistory[[#This Row],[Date]]-365)-1)-Dashboard!$G$17)/(Dashboard!$H$17-Dashboard!$G$17))),0)) | O10: =IF(tblHistory[[#This Row],[Date]]-MIN(tblHistory[Date])<364,NA(),IF(ISNUMBER(tblHistory[[#This Row],[BIZD]]),MIN(1,MAX(0,((tblHistory[[#This Row],[BIZD]]/_xlfn.MAXIFS(tblHistory[BIZD],tblHistory[Date],"<="&tblHistory[[#This Row],[Date]],tblHistory[Date],">="&tblHistory[[#This Row],[Date]]-365)-1)-Dashboard!$G$18)/(Dashboard!$H$18-Dashboard!$G$18))),0)) | P10: =IF(tblHistory[[#This Row],[Date]]-MIN(tblHistory[Date])<364,NA(),IF(ISNUMBER(tblHistory[[#This Row],[BKLN]]),MIN(1,MAX(0,((tblHistory[[#This Row],[BKLN]]/_xlfn.MAXIFS(tblHistory[BKLN],tblHistory[Date],"<="&tblHistory[[#This Row],[Date]],tblHistory[Date],">="&tblHistory[[#This Row],[Date]]-365)-1)-Dashboard!$G$19)/(Dashboard!$H$19-Dashboard!$G$19))),0)) | Q10: =IF(tblHistory[[#This Row],[Date]]-MIN(tblHistory[Date])<364,NA(),MIN(1,MAX(0,(IF(ISNUMBER(tblHistory[[#This Row],[HY]]),tblHistory[[#This Row],[HY]],SUMIFS(tblHistory[HY],tblHistory[Date],_xlfn.MAXIFS(tblHistory[Date],tblHistory[Date],"<"&tblHistory[[#This Row],[Date]],tblHistory[HY],"<>")))-Dashboard!$G$20)/(Dashboard!$H$20-Dashboard!$G$20)))) | R10: =(Dashboard!$C$13*tblHistory[[#This Row],[NDX S]]+Dashboard!$C$14*tblHistory[[#This Row],[SOX S]]+Dashboard!$C$15*tblHistory[[#This Row],[AIQ S]])/SUM(Dashboard!$C$13:$C$15)*100 | S10: =(Dashboard!$C$16*tblHistory[[#This Row],[ORCL S]]+Dashboard!$C$17*tblHistory[[#This Row],[CRWV S]])/SUM(Dashboard!$C$16:$C$17)*100 | T10: =(Dashboard!$C$18*tblHistory[[#This Row],[BIZD S]]+Dashboard!$C$19*tblHistory[[#This Row],[BKLN S]]+Dashboard!$C$20*tblHistory[[#This Row],[HY S]])/SUM(Dashboard!$C$18:$C$20)*100 | U10: =ROUND((Dashboard!$C$13*tblHistory[[#This Row],[NDX S]]+Dashboard!$C$14*tblHistory[[#This Row],[SOX S]]+Dashboard!$C$15*tblHistory[[#This Row],[AIQ S]]+Dashboard!$C$16*tblHistory[[#This Row],[ORCL S]]+Dashboard!$C$17*tblHistory[[#This Row],[CRWV S]]+Dashboard!$C$18*tblHistory[[#This Row],[BIZD S]]+Dashboard!$C$19*tblHistory[[#This Row],[BKLN S]]+Dashboard!$C$20*tblHistory[[#This Row],[HY S]])/SUM(Dashboard!$C$13:$C$20)*100,0) | V10: =IFERROR(--(tblHistory[[#This Row],[Score]]>=50),0) | W10: =IFERROR(--AND(tblHistory[[#This Row],[Score]]>=60,tblHistory[[#This Row],[BIZD S]]>=0.8,tblHistory[[#This Row],[BKLN S]]>=0.5),0) | X10: =IFERROR(--AND(tblHistory[[#This Row],[Score]]>=70,tblHistory[[#This Row],[SOX S]]>=0.83,tblHistory[[#This Row],[AIQ S]]>=0.8),0) | Y10: =IFERROR(--AND(tblHistory[[#This Row],[Score]]>=75,tblHistory[[#This Row],[NDX S]]=1,OR(IF(ISNUMBER(tblHistory[[#This Row],[HY]]),tblHistory[[#This Row],[HY]],SUMIFS(tblHistory[HY],tblHistory[Date],_xlfn.MAXIFS(tblHistory[Date],tblHistory[Date],"<"&tblHistory[[#This Row],[Date]],tblHistory[HY],"<>")))>=500,tblHistory[[#This Row],[BIZD S]]=1)),0) | Z10: =IFERROR(--(COUNTIFS(tblHistory[Date],">="&tblHistory[[#This Row],[Date]],tblHistory[Date],"<="&_xlfn.AGGREGATE(15,6,tblHistory[Date]/(tblHistory[Date]>=tblHistory[[#This Row],[Date]]),5),tblHistory[L1],1)=5),0) | AA10: =IFERROR(--(COUNTIFS(tblHistory[Date],">="&tblHistory[[#This Row],[Date]],tblHistory[Date],"<="&_xlfn.AGGREGATE(15,6,tblHistory[Date]/(tblHistory[Date]>=tblHistory[[#This Row],[Date]]),5),tblHistory[L2],1)=5),0) | AB10: =IFERROR(--(COUNTIFS(tblHistory[Date],">="&tblHistory[[#This Row],[Date]],tblHistory[Date],"<="&_xlfn.AGGREGATE(15,6,tblHistory[Date]/(tblHistory[Date]>=tblHistory[[#This Row],[Date]]),5),tblHistory[L3],1)=5),0) | AC10: =IFERROR(--(COUNTIFS(tblHistory[Date],">="&tblHistory[[#This Row],[Date]],tblHistory[Date],"<="&_xlfn.AGGREGATE(15,6,tblHistory[Date]/(tblHistory[Date]>=tblHistory[[#This Row],[Date]]),5),tblHistory[L4],1)=5),0)
A11: 46301 | B11: 24287.97 | C11: 9620.85 | D11: 40.93 | E11: 223.99 | F11: 39.02 | G11: 16.04 | H11: 20.86 | I11: 394 | J11: =IF(tblHistory[[#This Row],[Date]]-MIN(tblHistory[Date])<364,NA(),IF(ISNUMBER(tblHistory[[#This Row],[NDX]]),MIN(1,MAX(0,((tblHistory[[#This Row],[NDX]]/_xlfn.MAXIFS(tblHistory[NDX],tblHistory[Date],"<="&tblHistory[[#This Row],[Date]],tblHistory[Date],">="&tblHistory[[#This Row],[Date]]-365)-1)-Dashboard!$G$13)/(Dashboard!$H$13-Dashboard!$G$13))),0)) | K11: =IF(tblHistory[[#This Row],[Date]]-MIN(tblHistory[Date])<364,NA(),IF(ISNUMBER(tblHistory[[#This Row],[SOX]]),MIN(1,MAX(0,((tblHistory[[#This Row],[SOX]]/_xlfn.MAXIFS(tblHistory[SOX],tblHistory[Date],"<="&tblHistory[[#This Row],[Date]],tblHistory[Date],">="&tblHistory[[#This Row],[Date]]-365)-1)-Dashboard!$G$14)/(Dashboard!$H$14-Dashboard!$G$14))),0)) | L11: =IF(tblHistory[[#This Row],[Date]]-MIN(tblHistory[Date])<364,NA(),IF(ISNUMBER(tblHistory[[#This Row],[AIQ]]),MIN(1,MAX(0,((tblHistory[[#This Row],[AIQ]]/_xlfn.MAXIFS(tblHistory[AIQ],tblHistory[Date],"<="&tblHistory[[#This Row],[Date]],tblHistory[Date],">="&tblHistory[[#This Row],[Date]]-365)-1)-Dashboard!$G$15)/(Dashboard!$H$15-Dashboard!$G$15))),0)) | M11: =IF(tblHistory[[#This Row],[Date]]-MIN(tblHistory[Date])<364,NA(),IF(ISNUMBER(tblHistory[[#This Row],[ORCL]]),MIN(1,MAX(0,((tblHistory[[#This Row],[ORCL]]/_xlfn.MAXIFS(tblHistory[ORCL],tblHistory[Date],"<="&tblHistory[[#This Row],[Date]],tblHistory[Date],">="&tblHistory[[#This Row],[Date]]-365)-1)-Dashboard!$G$16)/(Dashboard!$H$16-Dashboard!$G$16))),0)) | N11: =IF(tblHistory[[#This Row],[Date]]-MIN(tblHistory[Date])<364,NA(),IF(ISNUMBER(tblHistory[[#This Row],[CRWV]]),MIN(1,MAX(0,((tblHistory[[#This Row],[CRWV]]/_xlfn.MAXIFS(tblHistory[CRWV],tblHistory[Date],"<="&tblHistory[[#This Row],[Date]],tblHistory[Date],">="&tblHistory[[#This Row],[Date]]-365)-1)-Dashboard!$G$17)/(Dashboard!$H$17-Dashboard!$G$17))),0)) | O11: =IF(tblHistory[[#This Row],[Date]]-MIN(tblHistory[Date])<364,NA(),IF(ISNUMBER(tblHistory[[#This Row],[BIZD]]),MIN(1,MAX(0,((tblHistory[[#This Row],[BIZD]]/_xlfn.MAXIFS(tblHistory[BIZD],tblHistory[Date],"<="&tblHistory[[#This Row],[Date]],tblHistory[Date],">="&tblHistory[[#This Row],[Date]]-365)-1)-Dashboard!$G$18)/(Dashboard!$H$18-Dashboard!$G$18))),0)) | P11: =IF(tblHistory[[#This Row],[Date]]-MIN(tblHistory[Date])<364,NA(),IF(ISNUMBER(tblHistory[[#This Row],[BKLN]]),MIN(1,MAX(0,((tblHistory[[#This Row],[BKLN]]/_xlfn.MAXIFS(tblHistory[BKLN],tblHistory[Date],"<="&tblHistory[[#This Row],[Date]],tblHistory[Date],">="&tblHistory[[#This Row],[Date]]-365)-1)-Dashboard!$G$19)/(Dashboard!$H$19-Dashboard!$G$19))),0)) | Q11: =IF(tblHistory[[#This Row],[Date]]-MIN(tblHistory[Date])<364,NA(),MIN(1,MAX(0,(IF(ISNUMBER(tblHistory[[#This Row],[HY]]),tblHistory[[#This Row],[HY]],SUMIFS(tblHistory[HY],tblHistory[Date],_xlfn.MAXIFS(tblHistory[Date],tblHistory[Date],"<"&tblHistory[[#This Row],[Date]],tblHistory[HY],"<>")))-Dashboard!$G$20)/(Dashboard!$H$20-Dashboard!$G$20)))) | R11: =(Dashboard!$C$13*tblHistory[[#This Row],[NDX S]]+Dashboard!$C$14*tblHistory[[#This Row],[SOX S]]+Dashboard!$C$15*tblHistory[[#This Row],[AIQ S]])/SUM(Dashboard!$C$13:$C$15)*100 | S11: =(Dashboard!$C$16*tblHistory[[#This Row],[ORCL S]]+Dashboard!$C$17*tblHistory[[#This Row],[CRWV S]])/SUM(Dashboard!$C$16:$C$17)*100 | T11: =(Dashboard!$C$18*tblHistory[[#This Row],[BIZD S]]+Dashboard!$C$19*tblHistory[[#This Row],[BKLN S]]+Dashboard!$C$20*tblHistory[[#This Row],[HY S]])/SUM(Dashboard!$C$18:$C$20)*100 | U11: =ROUND((Dashboard!$C$13*tblHistory[[#This Row],[NDX S]]+Dashboard!$C$14*tblHistory[[#This Row],[SOX S]]+Dashboard!$C$15*tblHistory[[#This Row],[AIQ S]]+Dashboard!$C$16*tblHistory[[#This Row],[ORCL S]]+Dashboard!$C$17*tblHistory[[#This Row],[CRWV S]]+Dashboard!$C$18*tblHistory[[#This Row],[BIZD S]]+Dashboard!$C$19*tblHistory[[#This Row],[BKLN S]]+Dashboard!$C$20*tblHistory[[#This Row],[HY S]])/SUM(Dashboard!$C$13:$C$20)*100,0) | V11: =IFERROR(--(tblHistory[[#This Row],[Score]]>=50),0) | W11: =IFERROR(--AND(tblHistory[[#This Row],[Score]]>=60,tblHistory[[#This Row],[BIZD S]]>=0.8,tblHistory[[#This Row],[BKLN S]]>=0.5),0) | X11: =IFERROR(--AND(tblHistory[[#This Row],[Score]]>=70,tblHistory[[#This Row],[SOX S]]>=0.83,tblHistory[[#This Row],[AIQ S]]>=0.8),0) | Y11: =IFERROR(--AND(tblHistory[[#This Row],[Score]]>=75,tblHistory[[#This Row],[NDX S]]=1,OR(IF(ISNUMBER(tblHistory[[#This Row],[HY]]),tblHistory[[#This Row],[HY]],SUMIFS(tblHistory[HY],tblHistory[Date],_xlfn.MAXIFS(tblHistory[Date],tblHistory[Date],"<"&tblHistory[[#This Row],[Date]],tblHistory[HY],"<>")))>=500,tblHistory[[#This Row],[BIZD S]]=1)),0) | Z11: =IFERROR(--(COUNTIFS(tblHistory[Date],">="&tblHistory[[#This Row],[Date]],tblHistory[Date],"<="&_xlfn.AGGREGATE(15,6,tblHistory[Date]/(tblHistory[Date]>=tblHistory[[#This Row],[Date]]),5),tblHistory[L1],1)=5),0) | AA11: =IFERROR(--(COUNTIFS(tblHistory[Date],">="&tblHistory[[#This Row],[Date]],tblHistory[Date],"<="&_xlfn.AGGREGATE(15,6,tblHistory[Date]/(tblHistory[Date]>=tblHistory[[#This Row],[Date]]),5),tblHistory[L2],1)=5),0) | AB11: =IFERROR(--(COUNTIFS(tblHistory[Date],">="&tblHistory[[#This Row],[Date]],tblHistory[Date],"<="&_xlfn.AGGREGATE(15,6,tblHistory[Date]/(tblHistory[Date]>=tblHistory[[#This Row],[Date]]),5),tblHistory[L3],1)=5),0) | AC11: =IFERROR(--(COUNTIFS(tblHistory[Date],">="&tblHistory[[#This Row],[Date]],tblHistory[Date],"<="&_xlfn.AGGREGATE(15,6,tblHistory[Date]/(tblHistory[Date]>=tblHistory[[#This Row],[Date]]),5),tblHistory[L4],1)=5),0)
A12: 46300 | B12: 24486.77 | C12: 9795.26 | D12: 41.44 | E12: 225.87 | F12: 38.04 | G12: 16.21 | H12: 20.86 | I12: 391 | J12: =IF(tblHistory[[#This Row],[Date]]-MIN(tblHistory[Date])<364,NA(),IF(ISNUMBER(tblHistory[[#This Row],[NDX]]),MIN(1,MAX(0,((tblHistory[[#This Row],[NDX]]/_xlfn.MAXIFS(tblHistory[NDX],tblHistory[Date],"<="&tblHistory[[#This Row],[Date]],tblHistory[Date],">="&tblHistory[[#This Row],[Date]]-365)-1)-Dashboard!$G$13)/(Dashboard!$H$13-Dashboard!$G$13))),0)) | K12: =IF(tblHistory[[#This Row],[Date]]-MIN(tblHistory[Date])<364,NA(),IF(ISNUMBER(tblHistory[[#This Row],[SOX]]),MIN(1,MAX(0,((tblHistory[[#This Row],[SOX]]/_xlfn.MAXIFS(tblHistory[SOX],tblHistory[Date],"<="&tblHistory[[#This Row],[Date]],tblHistory[Date],">="&tblHistory[[#This Row],[Date]]-365)-1)-Dashboard!$G$14)/(Dashboard!$H$14-Dashboard!$G$14))),0)) | L12: =IF(tblHistory[[#This Row],[Date]]-MIN(tblHistory[Date])<364,NA(),IF(ISNUMBER(tblHistory[[#This Row],[AIQ]]),MIN(1,MAX(0,((tblHistory[[#This Row],[AIQ]]/_xlfn.MAXIFS(tblHistory[AIQ],tblHistory[Date],"<="&tblHistory[[#This Row],[Date]],tblHistory[Date],">="&tblHistory[[#This Row],[Date]]-365)-1)-Dashboard!$G$15)/(Dashboard!$H$15-Dashboard!$G$15))),0)) | M12: =IF(tblHistory[[#This Row],[Date]]-MIN(tblHistory[Date])<364,NA(),IF(ISNUMBER(tblHistory[[#This Row],[ORCL]]),MIN(1,MAX(0,((tblHistory[[#This Row],[ORCL]]/_xlfn.MAXIFS(tblHistory[ORCL],tblHistory[Date],"<="&tblHistory[[#This Row],[Date]],tblHistory[Date],">="&tblHistory[[#This Row],[Date]]-365)-1)-Dashboard!$G$16)/(Dashboard!$H$16-Dashboard!$G$16))),0)) | N12: =IF(tblHistory[[#This Row],[Date]]-MIN(tblHistory[Date])<364,NA(),IF(ISNUMBER(tblHistory[[#This Row],[CRWV]]),MIN(1,MAX(0,((tblHistory[[#This Row],[CRWV]]/_xlfn.MAXIFS(tblHistory[CRWV],tblHistory[Date],"<="&tblHistory[[#This Row],[Date]],tblHistory[Date],">="&tblHistory[[#This Row],[Date]]-365)-1)-Dashboard!$G$17)/(Dashboard!$H$17-Dashboard!$G$17))),0)) | O12: =IF(tblHistory[[#This Row],[Date]]-MIN(tblHistory[Date])<364,NA(),IF(ISNUMBER(tblHistory[[#This Row],[BIZD]]),MIN(1,MAX(0,((tblHistory[[#This Row],[BIZD]]/_xlfn.MAXIFS(tblHistory[BIZD],tblHistory[Date],"<="&tblHistory[[#This Row],[Date]],tblHistory[Date],">="&tblHistory[[#This Row],[Date]]-365)-1)-Dashboard!$G$18)/(Dashboard!$H$18-Dashboard!$G$18))),0)) | P12: =IF(tblHistory[[#This Row],[Date]]-MIN(tblHistory[Date])<364,NA(),IF(ISNUMBER(tblHistory[[#This Row],[BKLN]]),MIN(1,MAX(0,((tblHistory[[#This Row],[BKLN]]/_xlfn.MAXIFS(tblHistory[BKLN],tblHistory[Date],"<="&tblHistory[[#This Row],[Date]],tblHistory[Date],">="&tblHistory[[#This Row],[Date]]-365)-1)-Dashboard!$G$19)/(Dashboard!$H$19-Dashboard!$G$19))),0)) | Q12: =IF(tblHistory[[#This Row],[Date]]-MIN(tblHistory[Date])<364,NA(),MIN(1,MAX(0,(IF(ISNUMBER(tblHistory[[#This Row],[HY]]),tblHistory[[#This Row],[HY]],SUMIFS(tblHistory[HY],tblHistory[Date],_xlfn.MAXIFS(tblHistory[Date],tblHistory[Date],"<"&tblHistory[[#This Row],[Date]],tblHistory[HY],"<>")))-Dashboard!$G$20)/(Dashboard!$H$20-Dashboard!$G$20)))) | R12: =(Dashboard!$C$13*tblHistory[[#This Row],[NDX S]]+Dashboard!$C$14*tblHistory[[#This Row],[SOX S]]+Dashboard!$C$15*tblHistory[[#This Row],[AIQ S]])/SUM(Dashboard!$C$13:$C$15)*100 | S12: =(Dashboard!$C$16*tblHistory[[#This Row],[ORCL S]]+Dashboard!$C$17*tblHistory[[#This Row],[CRWV S]])/SUM(Dashboard!$C$16:$C$17)*100 | T12: =(Dashboard!$C$18*tblHistory[[#This Row],[BIZD S]]+Dashboard!$C$19*tblHistory[[#This Row],[BKLN S]]+Dashboard!$C$20*tblHistory[[#This Row],[HY S]])/SUM(Dashboard!$C$18:$C$20)*100 | U12: =ROUND((Dashboard!$C$13*tblHistory[[#This Row],[NDX S]]+Dashboard!$C$14*tblHistory[[#This Row],[SOX S]]+Dashboard!$C$15*tblHistory[[#This Row],[AIQ S]]+Dashboard!$C$16*tblHistory[[#This Row],[ORCL S]]+Dashboard!$C$17*tblHistory[[#This Row],[CRWV S]]+Dashboard!$C$18*tblHistory[[#This Row],[BIZD S]]+Dashboard!$C$19*tblHistory[[#This Row],[BKLN S]]+Dashboard!$C$20*tblHistory[[#This Row],[HY S]])/SUM(Dashboard!$C$13:$C$20)*100,0) | V12: =IFERROR(--(tblHistory[[#This Row],[Score]]>=50),0) | W12: =IFERROR(--AND(tblHistory[[#This Row],[Score]]>=60,tblHistory[[#This Row],[BIZD S]]>=0.8,tblHistory[[#This Row],[BKLN S]]>=0.5),0) | X12: =IFERROR(--AND(tblHistory[[#This Row],[Score]]>=70,tblHistory[[#This Row],[SOX S]]>=0.83,tblHistory[[#This Row],[AIQ S]]>=0.8),0) | Y12: =IFERROR(--AND(tblHistory[[#This Row],[Score]]>=75,tblHistory[[#This Row],[NDX S]]=1,OR(IF(ISNUMBER(tblHistory[[#This Row],[HY]]),tblHistory[[#This Row],[HY]],SUMIFS(tblHistory[HY],tblHistory[Date],_xlfn.MAXIFS(tblHistory[Date],tblHistory[Date],"<"&tblHistory[[#This Row],[Date]],tblHistory[HY],"<>")))>=500,tblHistory[[#This Row],[BIZD S]]=1)),0) | Z12: =IFERROR(--(COUNTIFS(tblHistory[Date],">="&tblHistory[[#This Row],[Date]],tblHistory[Date],"<="&_xlfn.AGGREGATE(15,6,tblHistory[Date]/(tblHistory[Date]>=tblHistory[[#This Row],[Date]]),5),tblHistory[L1],1)=5),0) | AA12: =IFERROR(--(COUNTIFS(tblHistory[Date],">="&tblHistory[[#This Row],[Date]],tblHistory[Date],"<="&_xlfn.AGGREGATE(15,6,tblHistory[Date]/(tblHistory[Date]>=tblHistory[[#This Row],[Date]]),5),tblHistory[L2],1)=5),0) | AB12: =IFERROR(--(COUNTIFS(tblHistory[Date],">="&tblHistory[[#This Row],[Date]],tblHistory[Date],"<="&_xlfn.AGGREGATE(15,6,tblHistory[Date]/(tblHistory[Date]>=tblHistory[[#This Row],[Date]]),5),tblHistory[L3],1)=5),0) | AC12: =IFERROR(--(COUNTIFS(tblHistory[Date],">="&tblHistory[[#This Row],[Date]],tblHistory[Date],"<="&_xlfn.AGGREGATE(15,6,tblHistory[Date]/(tblHistory[Date]>=tblHistory[[#This Row],[Date]]),5),tblHistory[L4],1)=5),0)
